<?xml version="1.0"?>
<robot name="piper_arm" xmlns:xacro="http://ros.org/wiki/xacro">

  <xacro:macro name="piper_arm" params="
    parent
    prefix
    *origin">

    <joint name="${prefix}base_joint" type="fixed">
      <xacro:insert_block name="origin" />
      <parent link="${parent}"/>
      <child link="${prefix}base_link" />
    </joint>
    <link name="${prefix}base_link">
      <inertial>
        <origin xyz="-0.00974 0 0.04101" rpy="0 0 0" />
        <mass value="0.162" />
        <inertia
          ixx="0.000226592553127906"
          ixy="-7.33974356968813E-08"
          ixz="2.13221970218123E-06"
          iyy="0.000269447877479622"
          iyz="8.15167478685076E-09"
          izz="0.000222318286704" />
        </inertial>
      <visual>
        <geometry>
          <mesh filename="file://$(find piper_description)/meshes/base_link.dae" />
        </geometry>
      </visual>
      <collision>
        <geometry>
          <mesh filename="file://$(find piper_description)/meshes/base_link.dae" />
        </geometry>
      </collision>
    </link>
    <link name="${prefix}link_1">
      <inertial>
        <origin xyz="0.00131 0.00031 -0.00922" rpy="0 0 0" />
        <mass value="0.097" />
        <inertia
          ixx="7.76684558296781E-05"
          ixy="1.09084650459916E-07"
          ixz="-1.97480532432411E-06"
          iyy="9.24967780161546E-05"
          iyz="9.91284646834672E-07"
          izz="8.24589062407806E-05" />
      </inertial>
      <visual>
        <geometry>
          <mesh filename="file://$(find piper_description)/meshes/link1.dae" />
        </geometry>
      </visual>
      <collision>
        <geometry>
          <mesh filename="file://$(find piper_description)/meshes/link1.dae" />
        </geometry>
      </collision>
    </link>
    <joint name="${prefix}joint_1" type="revolute">
      <origin xyz="0 0 0.123" rpy="0 0 -${pi/2}" />
      <parent link="${prefix}base_link" />
      <child link="${prefix}link_1" />
      <axis xyz="0 0 1" />
      <limit lower="-2.68" upper="2.68" effort="100" velocity="3.14" />
    </joint>
    <link name="${prefix}link_2">
      <inertial>
        <origin xyz="0.14761 -0.01742 0.00175" rpy="0 0 0" />
        <mass value="0.289" />
        <inertia
          ixx="0.000150112628108228"
          ixy="8.58974959950769E-05"
          ixz="-1.07428153464285E-06"
          iyy="0.00172585302855383"
          iyz="-9.93704792239686E-07"
          izz="0.00177445942914759" />
      </inertial>
      <visual>
        <geometry>
          <mesh filename="file://$(find piper_description)/meshes/link2.dae" />
        </geometry>
      </visual>
      <collision>
        <geometry>
          <mesh filename="file://$(find piper_description)/meshes/link2.dae" />
        </geometry>
      </collision>
    </link>
    <joint name="${prefix}joint_2" type="revolute">
      <origin xyz="0 0 0" rpy="${pi/2} -0.10095 -${pi/2}" />
      <parent link="${prefix}link_1" />
      <child link="${prefix}link_2" />
      <axis xyz="0 0 1" />
      <limit lower="0" upper="3.4" effort="100" velocity="3.4" />
    </joint>
    <link name="${prefix}link_3">
      <inertial>
        <origin xyz="0.01567 0.10446 0.00050" rpy="0 0 0" />
        <mass value="0.290" />
        <inertia
          ixx="0.000221686352136266"
          ixy="-7.57426543992343E-06"
          ixz="-6.3700062772173E-07"
          iyy="0.000100859162015934"
          iyz="-8.16202696860781E-07"
          izz="0.000241839316548946" />
      </inertial>
      <visual>
        <geometry>

          <mesh filename="file://$(find piper_description)/meshes/link3.dae" />
        </geometry>
      </visual>
      <collision>
        <geometry>
          <mesh filename="file://$(find piper_description)/meshes/link3.dae" />
        </geometry>
      </collision>
    </link>
    <joint name="${prefix}joint_3" type="revolute">
      <origin xyz="0.28503 0 0" rpy="0 0 1.3826" />
      <parent link="${prefix}link_2" />
      <child link="${prefix}link_3" />
      <axis xyz="0 0 1" />
      <limit lower="-3.0" upper="0" effort="100" velocity="3.14" />
    </joint>
    <link name="${prefix}link_4">
      <inertial>
        <origin xyz="0.00027 -0.00102 -0.00472" rpy="0 0 0" />
        <mass value="0.127" />
        <inertia
          ixx="3.82011730423098E-05"
          ixy="-4.92358351033589E-08"
          ixz="4.89589432983109E-08"
          iyy="4.87048555222491E-05"
          iyz="6.70802942486707E-08"
          izz="4.10592077565155E-05" />
      </inertial>
      <visual>
        <geometry>
          <mesh filename="file://$(find piper_description)/meshes/link4.dae" />
        </geometry>
      </visual>
      <collision>
        <geometry>
          <mesh filename="file://$(find piper_description)/meshes/link4.dae" />
        </geometry>
      </collision>
    </link>
    <joint name="${prefix}joint_4" type="revolute">
      <origin xyz="0.021984 0.25075 0" rpy="-${pi/2} 0 0" />
      <parent link="${prefix}link_3" />
      <child link="${prefix}link_4" />
      <axis xyz="0 0 -1" />
      <limit lower="-1.85" upper="1.85" effort="100" velocity="3.93" />
    </joint>
    <link name="${prefix}link_5">
      <inertial>
        <origin xyz="0 0.05668 -0.00196" rpy="0 0 0" />
        <mass value="0.1447" />
        <inertia
          ixx="4.39644269159173E-05"
          ixy="-3.59214840853815E-08"
          ixz="-1.89785003257649E-08"
          iyy="5.63173857792457E-05"
          iyz="-2.15407623722543E-07"
          izz="4.88713595021005E-05" />
      </inertial>
      <visual>
        <geometry>
          <mesh filename="file://$(find piper_description)/meshes/link5.dae" />
        </geometry>
      </visual>
      <collision>
        <geometry>
          <mesh filename="file://$(find piper_description)/meshes/link5.dae" />
        </geometry>
      </collision>
    </link>
    <joint name="${prefix}joint_5" type="revolute">
      <origin xyz="0 0 0" rpy="${pi/2} -0.087266 0" />
      <parent link="${prefix}link_4" />
      <child link="${prefix}link_5" />
      <axis xyz="0 0 1" />
      <limit lower="-1.3" upper="1.3" effort="100" velocity="3.93" />
    </joint>
    <link name="${prefix}link_6" />
    <joint name="${prefix}joint_6" type="revolute">
      <origin xyz="0 0.091 0.0014" rpy="-${pi/2} 0 0" />
      <parent link="${prefix}link_5" />
      <child link="${prefix}link_6" />
      <axis xyz="0 0 -1" />
      <limit lower="-${pi}" upper="${pi}" effort="100" velocity="3.93" />
    </joint>
    <link name="${prefix}tool_0" />
    <joint name="${prefix}tool_0_joint" type="fixed">
      <origin xyz="0 0 0" rpy="0 0 0" />
      <parent link="${prefix}link_6" />
      <child link="${prefix}tool_0" />
    </joint>
  </xacro:macro>
</robot>
